{
 "cells": [
  {
   "cell_type": "code",
   "execution_count": 20,
   "id": "158209ca-29b5-4baf-b1f5-cb61e59c09d5",
   "metadata": {},
   "outputs": [],
   "source": [
    "docs = ['go india',\n",
    "\t\t'india india',\n",
    "\t\t'hip hip hurray',\n",
    "\t\t'jeetega bhai jeetega india jeetega',\n",
    "\t\t'bharat mata ki jai',\n",
    "\t\t'kohli kohli',\n",
    "\t\t'sachin sachin',\n",
    "\t\t'dhoni dhoni',\n",
    "\t\t'modi ji ki jai',\n",
    "\t\t'inquilab zindabad']"
   ]
  },
  {
   "cell_type": "code",
   "execution_count": 21,
   "id": "66b8d8ee-10b0-4060-83a8-3c1f9a0ef0ff",
   "metadata": {},
   "outputs": [],
   "source": [
    "from keras.preprocessing.text import Tokenizer"
   ]
  },
  {
   "cell_type": "code",
   "execution_count": 22,
   "id": "35770af2-2c8c-427c-bc6f-b8d7050bcbbe",
   "metadata": {},
   "outputs": [],
   "source": [
    "tokenizer = Tokenizer()"
   ]
  },
  {
   "cell_type": "code",
   "execution_count": 23,
   "id": "aacf6445-076a-4770-819d-6a064aeb010e",
   "metadata": {},
   "outputs": [],
   "source": [
    "tokenizer.fit_on_texts(docs)"
   ]
  },
  {
   "cell_type": "code",
   "execution_count": 24,
   "id": "36d15bef-1629-43be-88e5-38d15c9b4b88",
   "metadata": {},
   "outputs": [
    {
     "data": {
      "text/plain": [
       "17"
      ]
     },
     "execution_count": 24,
     "metadata": {},
     "output_type": "execute_result"
    }
   ],
   "source": [
    "len(tokenizer.word_index)"
   ]
  },
  {
   "cell_type": "code",
   "execution_count": 25,
   "id": "aab833e7-ace8-466f-934a-5a0ba02bec04",
   "metadata": {},
   "outputs": [
    {
     "data": {
      "text/plain": [
       "[[9, 1],\n",
       " [1, 1],\n",
       " [3, 3, 10],\n",
       " [2, 11, 2, 1, 2],\n",
       " [12, 13, 4, 5],\n",
       " [6, 6],\n",
       " [7, 7],\n",
       " [8, 8],\n",
       " [14, 15, 4, 5],\n",
       " [16, 17]]"
      ]
     },
     "execution_count": 25,
     "metadata": {},
     "output_type": "execute_result"
    }
   ],
   "source": [
    "seqeunces = tokenizer.texts_to_sequences(docs)\n",
    "seqeunces"
   ]
  },
  {
   "cell_type": "code",
   "execution_count": 26,
   "id": "ca353c8a-5fe5-4099-8720-c9b526723ffb",
   "metadata": {},
   "outputs": [
    {
     "data": {
      "text/plain": [
       "array([[ 9,  1,  0,  0,  0],\n",
       "       [ 1,  1,  0,  0,  0],\n",
       "       [ 3,  3, 10,  0,  0],\n",
       "       [ 2, 11,  2,  1,  2],\n",
       "       [12, 13,  4,  5,  0],\n",
       "       [ 6,  6,  0,  0,  0],\n",
       "       [ 7,  7,  0,  0,  0],\n",
       "       [ 8,  8,  0,  0,  0],\n",
       "       [14, 15,  4,  5,  0],\n",
       "       [16, 17,  0,  0,  0]])"
      ]
     },
     "execution_count": 26,
     "metadata": {},
     "output_type": "execute_result"
    }
   ],
   "source": [
    "from keras.utils import pad_sequences\n",
    "seqeunces = pad_sequences(seqeunces, padding='post')\n",
    "seqeunces"
   ]
  },
  {
   "cell_type": "code",
   "execution_count": 27,
   "id": "dcb7051a-3659-4a82-ab5d-acc1ac3df781",
   "metadata": {},
   "outputs": [
    {
     "name": "stdout",
     "output_type": "stream",
     "text": [
      "Model: \"sequential_4\"\n",
      "_________________________________________________________________\n",
      " Layer (type)                Output Shape              Param #   \n",
      "=================================================================\n",
      " embedding_1 (Embedding)     (None, 5, 2)              34        \n",
      "                                                                 \n",
      "=================================================================\n",
      "Total params: 34 (136.00 Byte)\n",
      "Trainable params: 34 (136.00 Byte)\n",
      "Non-trainable params: 0 (0.00 Byte)\n",
      "_________________________________________________________________\n"
     ]
    }
   ],
   "source": [
    "from keras import Sequential\n",
    "from keras.layers import Embedding\n",
    "model = Sequential()\n",
    "model.add(Embedding(17,output_dim=2,input_length=5))\n",
    "model.summary()"
   ]
  },
  {
   "cell_type": "code",
   "execution_count": 28,
   "id": "f3f4423d-0c95-4b2a-9192-ce1515c0c3a4",
   "metadata": {},
   "outputs": [],
   "source": [
    "model.compile('adam','accuracy')"
   ]
  },
  {
   "cell_type": "code",
   "execution_count": 31,
   "id": "f11bd0c5-bb84-44c0-be00-4cdc35f2a7fc",
   "metadata": {},
   "outputs": [
    {
     "name": "stdout",
     "output_type": "stream",
     "text": [
      "An error occurred: Graph execution error:\n",
      "\n",
      "Detected at node sequential_4/embedding_1/embedding_lookup defined at (most recent call last):\n",
      "  File \"<frozen runpy>\", line 198, in _run_module_as_main\n",
      "\n",
      "  File \"<frozen runpy>\", line 88, in _run_code\n",
      "\n",
      "  File \"C:\\Users\\harik\\AppData\\Local\\Packages\\PythonSoftwareFoundation.Python.3.11_qbz5n2kfra8p0\\LocalCache\\local-packages\\Python311\\site-packages\\ipykernel_launcher.py\", line 17, in <module>\n",
      "\n",
      "  File \"C:\\Users\\harik\\AppData\\Local\\Packages\\PythonSoftwareFoundation.Python.3.11_qbz5n2kfra8p0\\LocalCache\\local-packages\\Python311\\site-packages\\traitlets\\config\\application.py\", line 1043, in launch_instance\n",
      "\n",
      "  File \"C:\\Users\\harik\\AppData\\Local\\Packages\\PythonSoftwareFoundation.Python.3.11_qbz5n2kfra8p0\\LocalCache\\local-packages\\Python311\\site-packages\\ipykernel\\kernelapp.py\", line 725, in start\n",
      "\n",
      "  File \"C:\\Users\\harik\\AppData\\Local\\Packages\\PythonSoftwareFoundation.Python.3.11_qbz5n2kfra8p0\\LocalCache\\local-packages\\Python311\\site-packages\\tornado\\platform\\asyncio.py\", line 195, in start\n",
      "\n",
      "  File \"C:\\Program Files\\WindowsApps\\PythonSoftwareFoundation.Python.3.11_3.11.2032.0_x64__qbz5n2kfra8p0\\Lib\\asyncio\\base_events.py\", line 607, in run_forever\n",
      "\n",
      "  File \"C:\\Program Files\\WindowsApps\\PythonSoftwareFoundation.Python.3.11_3.11.2032.0_x64__qbz5n2kfra8p0\\Lib\\asyncio\\base_events.py\", line 1922, in _run_once\n",
      "\n",
      "  File \"C:\\Program Files\\WindowsApps\\PythonSoftwareFoundation.Python.3.11_3.11.2032.0_x64__qbz5n2kfra8p0\\Lib\\asyncio\\events.py\", line 80, in _run\n",
      "\n",
      "  File \"C:\\Users\\harik\\AppData\\Local\\Packages\\PythonSoftwareFoundation.Python.3.11_qbz5n2kfra8p0\\LocalCache\\local-packages\\Python311\\site-packages\\ipykernel\\kernelbase.py\", line 513, in dispatch_queue\n",
      "\n",
      "  File \"C:\\Users\\harik\\AppData\\Local\\Packages\\PythonSoftwareFoundation.Python.3.11_qbz5n2kfra8p0\\LocalCache\\local-packages\\Python311\\site-packages\\ipykernel\\kernelbase.py\", line 502, in process_one\n",
      "\n",
      "  File \"C:\\Users\\harik\\AppData\\Local\\Packages\\PythonSoftwareFoundation.Python.3.11_qbz5n2kfra8p0\\LocalCache\\local-packages\\Python311\\site-packages\\ipykernel\\kernelbase.py\", line 409, in dispatch_shell\n",
      "\n",
      "  File \"C:\\Users\\harik\\AppData\\Local\\Packages\\PythonSoftwareFoundation.Python.3.11_qbz5n2kfra8p0\\LocalCache\\local-packages\\Python311\\site-packages\\ipykernel\\kernelbase.py\", line 729, in execute_request\n",
      "\n",
      "  File \"C:\\Users\\harik\\AppData\\Local\\Packages\\PythonSoftwareFoundation.Python.3.11_qbz5n2kfra8p0\\LocalCache\\local-packages\\Python311\\site-packages\\ipykernel\\ipkernel.py\", line 422, in do_execute\n",
      "\n",
      "  File \"C:\\Users\\harik\\AppData\\Local\\Packages\\PythonSoftwareFoundation.Python.3.11_qbz5n2kfra8p0\\LocalCache\\local-packages\\Python311\\site-packages\\ipykernel\\zmqshell.py\", line 540, in run_cell\n",
      "\n",
      "  File \"C:\\Users\\harik\\AppData\\Local\\Packages\\PythonSoftwareFoundation.Python.3.11_qbz5n2kfra8p0\\LocalCache\\local-packages\\Python311\\site-packages\\IPython\\core\\interactiveshell.py\", line 3009, in run_cell\n",
      "\n",
      "  File \"C:\\Users\\harik\\AppData\\Local\\Packages\\PythonSoftwareFoundation.Python.3.11_qbz5n2kfra8p0\\LocalCache\\local-packages\\Python311\\site-packages\\IPython\\core\\interactiveshell.py\", line 3064, in _run_cell\n",
      "\n",
      "  File \"C:\\Users\\harik\\AppData\\Local\\Packages\\PythonSoftwareFoundation.Python.3.11_qbz5n2kfra8p0\\LocalCache\\local-packages\\Python311\\site-packages\\IPython\\core\\async_helpers.py\", line 129, in _pseudo_sync_runner\n",
      "\n",
      "  File \"C:\\Users\\harik\\AppData\\Local\\Packages\\PythonSoftwareFoundation.Python.3.11_qbz5n2kfra8p0\\LocalCache\\local-packages\\Python311\\site-packages\\IPython\\core\\interactiveshell.py\", line 3269, in run_cell_async\n",
      "\n",
      "  File \"C:\\Users\\harik\\AppData\\Local\\Packages\\PythonSoftwareFoundation.Python.3.11_qbz5n2kfra8p0\\LocalCache\\local-packages\\Python311\\site-packages\\IPython\\core\\interactiveshell.py\", line 3448, in run_ast_nodes\n",
      "\n",
      "  File \"C:\\Users\\harik\\AppData\\Local\\Packages\\PythonSoftwareFoundation.Python.3.11_qbz5n2kfra8p0\\LocalCache\\local-packages\\Python311\\site-packages\\IPython\\core\\interactiveshell.py\", line 3508, in run_code\n",
      "\n",
      "  File \"C:\\Users\\harik\\AppData\\Local\\Temp\\ipykernel_7232\\1334315659.py\", line 1, in <module>\n",
      "\n",
      "  File \"C:\\Users\\harik\\AppData\\Local\\Packages\\PythonSoftwareFoundation.Python.3.11_qbz5n2kfra8p0\\LocalCache\\local-packages\\Python311\\site-packages\\keras\\src\\utils\\traceback_utils.py\", line 65, in error_handler\n",
      "\n",
      "  File \"C:\\Users\\harik\\AppData\\Local\\Packages\\PythonSoftwareFoundation.Python.3.11_qbz5n2kfra8p0\\LocalCache\\local-packages\\Python311\\site-packages\\keras\\src\\engine\\training.py\", line 2655, in predict\n",
      "\n",
      "  File \"C:\\Users\\harik\\AppData\\Local\\Packages\\PythonSoftwareFoundation.Python.3.11_qbz5n2kfra8p0\\LocalCache\\local-packages\\Python311\\site-packages\\keras\\src\\engine\\training.py\", line 2440, in predict_function\n",
      "\n",
      "  File \"C:\\Users\\harik\\AppData\\Local\\Packages\\PythonSoftwareFoundation.Python.3.11_qbz5n2kfra8p0\\LocalCache\\local-packages\\Python311\\site-packages\\keras\\src\\engine\\training.py\", line 2425, in step_function\n",
      "\n",
      "  File \"C:\\Users\\harik\\AppData\\Local\\Packages\\PythonSoftwareFoundation.Python.3.11_qbz5n2kfra8p0\\LocalCache\\local-packages\\Python311\\site-packages\\keras\\src\\engine\\training.py\", line 2413, in run_step\n",
      "\n",
      "  File \"C:\\Users\\harik\\AppData\\Local\\Packages\\PythonSoftwareFoundation.Python.3.11_qbz5n2kfra8p0\\LocalCache\\local-packages\\Python311\\site-packages\\keras\\src\\engine\\training.py\", line 2381, in predict_step\n",
      "\n",
      "  File \"C:\\Users\\harik\\AppData\\Local\\Packages\\PythonSoftwareFoundation.Python.3.11_qbz5n2kfra8p0\\LocalCache\\local-packages\\Python311\\site-packages\\keras\\src\\utils\\traceback_utils.py\", line 65, in error_handler\n",
      "\n",
      "  File \"C:\\Users\\harik\\AppData\\Local\\Packages\\PythonSoftwareFoundation.Python.3.11_qbz5n2kfra8p0\\LocalCache\\local-packages\\Python311\\site-packages\\keras\\src\\engine\\training.py\", line 590, in __call__\n",
      "\n",
      "  File \"C:\\Users\\harik\\AppData\\Local\\Packages\\PythonSoftwareFoundation.Python.3.11_qbz5n2kfra8p0\\LocalCache\\local-packages\\Python311\\site-packages\\keras\\src\\utils\\traceback_utils.py\", line 65, in error_handler\n",
      "\n",
      "  File \"C:\\Users\\harik\\AppData\\Local\\Packages\\PythonSoftwareFoundation.Python.3.11_qbz5n2kfra8p0\\LocalCache\\local-packages\\Python311\\site-packages\\keras\\src\\engine\\base_layer.py\", line 1149, in __call__\n",
      "\n",
      "  File \"C:\\Users\\harik\\AppData\\Local\\Packages\\PythonSoftwareFoundation.Python.3.11_qbz5n2kfra8p0\\LocalCache\\local-packages\\Python311\\site-packages\\keras\\src\\utils\\traceback_utils.py\", line 96, in error_handler\n",
      "\n",
      "  File \"C:\\Users\\harik\\AppData\\Local\\Packages\\PythonSoftwareFoundation.Python.3.11_qbz5n2kfra8p0\\LocalCache\\local-packages\\Python311\\site-packages\\keras\\src\\engine\\sequential.py\", line 398, in call\n",
      "\n",
      "  File \"C:\\Users\\harik\\AppData\\Local\\Packages\\PythonSoftwareFoundation.Python.3.11_qbz5n2kfra8p0\\LocalCache\\local-packages\\Python311\\site-packages\\keras\\src\\engine\\functional.py\", line 515, in call\n",
      "\n",
      "  File \"C:\\Users\\harik\\AppData\\Local\\Packages\\PythonSoftwareFoundation.Python.3.11_qbz5n2kfra8p0\\LocalCache\\local-packages\\Python311\\site-packages\\keras\\src\\engine\\functional.py\", line 672, in _run_internal_graph\n",
      "\n",
      "  File \"C:\\Users\\harik\\AppData\\Local\\Packages\\PythonSoftwareFoundation.Python.3.11_qbz5n2kfra8p0\\LocalCache\\local-packages\\Python311\\site-packages\\keras\\src\\utils\\traceback_utils.py\", line 65, in error_handler\n",
      "\n",
      "  File \"C:\\Users\\harik\\AppData\\Local\\Packages\\PythonSoftwareFoundation.Python.3.11_qbz5n2kfra8p0\\LocalCache\\local-packages\\Python311\\site-packages\\keras\\src\\engine\\base_layer.py\", line 1149, in __call__\n",
      "\n",
      "  File \"C:\\Users\\harik\\AppData\\Local\\Packages\\PythonSoftwareFoundation.Python.3.11_qbz5n2kfra8p0\\LocalCache\\local-packages\\Python311\\site-packages\\keras\\src\\utils\\traceback_utils.py\", line 96, in error_handler\n",
      "\n",
      "  File \"C:\\Users\\harik\\AppData\\Local\\Packages\\PythonSoftwareFoundation.Python.3.11_qbz5n2kfra8p0\\LocalCache\\local-packages\\Python311\\site-packages\\keras\\src\\layers\\core\\embedding.py\", line 272, in call\n",
      "\n",
      "indices[9,1] = 17 is not in [0, 17)\n",
      "\t [[{{node sequential_4/embedding_1/embedding_lookup}}]] [Op:__inference_predict_function_406]\n"
     ]
    },
    {
     "ename": "NameError",
     "evalue": "name 'sequences' is not defined",
     "output_type": "error",
     "traceback": [
      "\u001b[1;31m---------------------------------------------------------------------------\u001b[0m",
      "\u001b[1;31mInvalidArgumentError\u001b[0m                      Traceback (most recent call last)",
      "Cell \u001b[1;32mIn[31], line 2\u001b[0m\n\u001b[0;32m      1\u001b[0m \u001b[38;5;28;01mtry\u001b[39;00m:\n\u001b[1;32m----> 2\u001b[0m     pred \u001b[38;5;241m=\u001b[39m \u001b[43mmodel\u001b[49m\u001b[38;5;241;43m.\u001b[39;49m\u001b[43mpredict\u001b[49m\u001b[43m(\u001b[49m\u001b[43mseqeunces\u001b[49m\u001b[43m)\u001b[49m\n\u001b[0;32m      3\u001b[0m     \u001b[38;5;28mprint\u001b[39m(pred)\n",
      "File \u001b[1;32m~\\AppData\\Local\\Packages\\PythonSoftwareFoundation.Python.3.11_qbz5n2kfra8p0\\LocalCache\\local-packages\\Python311\\site-packages\\keras\\src\\utils\\traceback_utils.py:70\u001b[0m, in \u001b[0;36mfilter_traceback.<locals>.error_handler\u001b[1;34m(*args, **kwargs)\u001b[0m\n\u001b[0;32m     68\u001b[0m     \u001b[38;5;66;03m# To get the full stack trace, call:\u001b[39;00m\n\u001b[0;32m     69\u001b[0m     \u001b[38;5;66;03m# `tf.debugging.disable_traceback_filtering()`\u001b[39;00m\n\u001b[1;32m---> 70\u001b[0m     \u001b[38;5;28;01mraise\u001b[39;00m e\u001b[38;5;241m.\u001b[39mwith_traceback(filtered_tb) \u001b[38;5;28;01mfrom\u001b[39;00m \u001b[38;5;28;01mNone\u001b[39;00m\n\u001b[0;32m     71\u001b[0m \u001b[38;5;28;01mfinally\u001b[39;00m:\n",
      "File \u001b[1;32m~\\AppData\\Local\\Packages\\PythonSoftwareFoundation.Python.3.11_qbz5n2kfra8p0\\LocalCache\\local-packages\\Python311\\site-packages\\tensorflow\\python\\eager\\execute.py:53\u001b[0m, in \u001b[0;36mquick_execute\u001b[1;34m(op_name, num_outputs, inputs, attrs, ctx, name)\u001b[0m\n\u001b[0;32m     52\u001b[0m   ctx\u001b[38;5;241m.\u001b[39mensure_initialized()\n\u001b[1;32m---> 53\u001b[0m   tensors \u001b[38;5;241m=\u001b[39m pywrap_tfe\u001b[38;5;241m.\u001b[39mTFE_Py_Execute(ctx\u001b[38;5;241m.\u001b[39m_handle, device_name, op_name,\n\u001b[0;32m     54\u001b[0m                                       inputs, attrs, num_outputs)\n\u001b[0;32m     55\u001b[0m \u001b[38;5;28;01mexcept\u001b[39;00m core\u001b[38;5;241m.\u001b[39m_NotOkStatusException \u001b[38;5;28;01mas\u001b[39;00m e:\n",
      "\u001b[1;31mInvalidArgumentError\u001b[0m: Graph execution error:\n\nDetected at node sequential_4/embedding_1/embedding_lookup defined at (most recent call last):\n  File \"<frozen runpy>\", line 198, in _run_module_as_main\n\n  File \"<frozen runpy>\", line 88, in _run_code\n\n  File \"C:\\Users\\harik\\AppData\\Local\\Packages\\PythonSoftwareFoundation.Python.3.11_qbz5n2kfra8p0\\LocalCache\\local-packages\\Python311\\site-packages\\ipykernel_launcher.py\", line 17, in <module>\n\n  File \"C:\\Users\\harik\\AppData\\Local\\Packages\\PythonSoftwareFoundation.Python.3.11_qbz5n2kfra8p0\\LocalCache\\local-packages\\Python311\\site-packages\\traitlets\\config\\application.py\", line 1043, in launch_instance\n\n  File \"C:\\Users\\harik\\AppData\\Local\\Packages\\PythonSoftwareFoundation.Python.3.11_qbz5n2kfra8p0\\LocalCache\\local-packages\\Python311\\site-packages\\ipykernel\\kernelapp.py\", line 725, in start\n\n  File \"C:\\Users\\harik\\AppData\\Local\\Packages\\PythonSoftwareFoundation.Python.3.11_qbz5n2kfra8p0\\LocalCache\\local-packages\\Python311\\site-packages\\tornado\\platform\\asyncio.py\", line 195, in start\n\n  File \"C:\\Program Files\\WindowsApps\\PythonSoftwareFoundation.Python.3.11_3.11.2032.0_x64__qbz5n2kfra8p0\\Lib\\asyncio\\base_events.py\", line 607, in run_forever\n\n  File \"C:\\Program Files\\WindowsApps\\PythonSoftwareFoundation.Python.3.11_3.11.2032.0_x64__qbz5n2kfra8p0\\Lib\\asyncio\\base_events.py\", line 1922, in _run_once\n\n  File \"C:\\Program Files\\WindowsApps\\PythonSoftwareFoundation.Python.3.11_3.11.2032.0_x64__qbz5n2kfra8p0\\Lib\\asyncio\\events.py\", line 80, in _run\n\n  File \"C:\\Users\\harik\\AppData\\Local\\Packages\\PythonSoftwareFoundation.Python.3.11_qbz5n2kfra8p0\\LocalCache\\local-packages\\Python311\\site-packages\\ipykernel\\kernelbase.py\", line 513, in dispatch_queue\n\n  File \"C:\\Users\\harik\\AppData\\Local\\Packages\\PythonSoftwareFoundation.Python.3.11_qbz5n2kfra8p0\\LocalCache\\local-packages\\Python311\\site-packages\\ipykernel\\kernelbase.py\", line 502, in process_one\n\n  File \"C:\\Users\\harik\\AppData\\Local\\Packages\\PythonSoftwareFoundation.Python.3.11_qbz5n2kfra8p0\\LocalCache\\local-packages\\Python311\\site-packages\\ipykernel\\kernelbase.py\", line 409, in dispatch_shell\n\n  File \"C:\\Users\\harik\\AppData\\Local\\Packages\\PythonSoftwareFoundation.Python.3.11_qbz5n2kfra8p0\\LocalCache\\local-packages\\Python311\\site-packages\\ipykernel\\kernelbase.py\", line 729, in execute_request\n\n  File \"C:\\Users\\harik\\AppData\\Local\\Packages\\PythonSoftwareFoundation.Python.3.11_qbz5n2kfra8p0\\LocalCache\\local-packages\\Python311\\site-packages\\ipykernel\\ipkernel.py\", line 422, in do_execute\n\n  File \"C:\\Users\\harik\\AppData\\Local\\Packages\\PythonSoftwareFoundation.Python.3.11_qbz5n2kfra8p0\\LocalCache\\local-packages\\Python311\\site-packages\\ipykernel\\zmqshell.py\", line 540, in run_cell\n\n  File \"C:\\Users\\harik\\AppData\\Local\\Packages\\PythonSoftwareFoundation.Python.3.11_qbz5n2kfra8p0\\LocalCache\\local-packages\\Python311\\site-packages\\IPython\\core\\interactiveshell.py\", line 3009, in run_cell\n\n  File \"C:\\Users\\harik\\AppData\\Local\\Packages\\PythonSoftwareFoundation.Python.3.11_qbz5n2kfra8p0\\LocalCache\\local-packages\\Python311\\site-packages\\IPython\\core\\interactiveshell.py\", line 3064, in _run_cell\n\n  File \"C:\\Users\\harik\\AppData\\Local\\Packages\\PythonSoftwareFoundation.Python.3.11_qbz5n2kfra8p0\\LocalCache\\local-packages\\Python311\\site-packages\\IPython\\core\\async_helpers.py\", line 129, in _pseudo_sync_runner\n\n  File \"C:\\Users\\harik\\AppData\\Local\\Packages\\PythonSoftwareFoundation.Python.3.11_qbz5n2kfra8p0\\LocalCache\\local-packages\\Python311\\site-packages\\IPython\\core\\interactiveshell.py\", line 3269, in run_cell_async\n\n  File \"C:\\Users\\harik\\AppData\\Local\\Packages\\PythonSoftwareFoundation.Python.3.11_qbz5n2kfra8p0\\LocalCache\\local-packages\\Python311\\site-packages\\IPython\\core\\interactiveshell.py\", line 3448, in run_ast_nodes\n\n  File \"C:\\Users\\harik\\AppData\\Local\\Packages\\PythonSoftwareFoundation.Python.3.11_qbz5n2kfra8p0\\LocalCache\\local-packages\\Python311\\site-packages\\IPython\\core\\interactiveshell.py\", line 3508, in run_code\n\n  File \"C:\\Users\\harik\\AppData\\Local\\Temp\\ipykernel_7232\\1334315659.py\", line 1, in <module>\n\n  File \"C:\\Users\\harik\\AppData\\Local\\Packages\\PythonSoftwareFoundation.Python.3.11_qbz5n2kfra8p0\\LocalCache\\local-packages\\Python311\\site-packages\\keras\\src\\utils\\traceback_utils.py\", line 65, in error_handler\n\n  File \"C:\\Users\\harik\\AppData\\Local\\Packages\\PythonSoftwareFoundation.Python.3.11_qbz5n2kfra8p0\\LocalCache\\local-packages\\Python311\\site-packages\\keras\\src\\engine\\training.py\", line 2655, in predict\n\n  File \"C:\\Users\\harik\\AppData\\Local\\Packages\\PythonSoftwareFoundation.Python.3.11_qbz5n2kfra8p0\\LocalCache\\local-packages\\Python311\\site-packages\\keras\\src\\engine\\training.py\", line 2440, in predict_function\n\n  File \"C:\\Users\\harik\\AppData\\Local\\Packages\\PythonSoftwareFoundation.Python.3.11_qbz5n2kfra8p0\\LocalCache\\local-packages\\Python311\\site-packages\\keras\\src\\engine\\training.py\", line 2425, in step_function\n\n  File \"C:\\Users\\harik\\AppData\\Local\\Packages\\PythonSoftwareFoundation.Python.3.11_qbz5n2kfra8p0\\LocalCache\\local-packages\\Python311\\site-packages\\keras\\src\\engine\\training.py\", line 2413, in run_step\n\n  File \"C:\\Users\\harik\\AppData\\Local\\Packages\\PythonSoftwareFoundation.Python.3.11_qbz5n2kfra8p0\\LocalCache\\local-packages\\Python311\\site-packages\\keras\\src\\engine\\training.py\", line 2381, in predict_step\n\n  File \"C:\\Users\\harik\\AppData\\Local\\Packages\\PythonSoftwareFoundation.Python.3.11_qbz5n2kfra8p0\\LocalCache\\local-packages\\Python311\\site-packages\\keras\\src\\utils\\traceback_utils.py\", line 65, in error_handler\n\n  File \"C:\\Users\\harik\\AppData\\Local\\Packages\\PythonSoftwareFoundation.Python.3.11_qbz5n2kfra8p0\\LocalCache\\local-packages\\Python311\\site-packages\\keras\\src\\engine\\training.py\", line 590, in __call__\n\n  File \"C:\\Users\\harik\\AppData\\Local\\Packages\\PythonSoftwareFoundation.Python.3.11_qbz5n2kfra8p0\\LocalCache\\local-packages\\Python311\\site-packages\\keras\\src\\utils\\traceback_utils.py\", line 65, in error_handler\n\n  File \"C:\\Users\\harik\\AppData\\Local\\Packages\\PythonSoftwareFoundation.Python.3.11_qbz5n2kfra8p0\\LocalCache\\local-packages\\Python311\\site-packages\\keras\\src\\engine\\base_layer.py\", line 1149, in __call__\n\n  File \"C:\\Users\\harik\\AppData\\Local\\Packages\\PythonSoftwareFoundation.Python.3.11_qbz5n2kfra8p0\\LocalCache\\local-packages\\Python311\\site-packages\\keras\\src\\utils\\traceback_utils.py\", line 96, in error_handler\n\n  File \"C:\\Users\\harik\\AppData\\Local\\Packages\\PythonSoftwareFoundation.Python.3.11_qbz5n2kfra8p0\\LocalCache\\local-packages\\Python311\\site-packages\\keras\\src\\engine\\sequential.py\", line 398, in call\n\n  File \"C:\\Users\\harik\\AppData\\Local\\Packages\\PythonSoftwareFoundation.Python.3.11_qbz5n2kfra8p0\\LocalCache\\local-packages\\Python311\\site-packages\\keras\\src\\engine\\functional.py\", line 515, in call\n\n  File \"C:\\Users\\harik\\AppData\\Local\\Packages\\PythonSoftwareFoundation.Python.3.11_qbz5n2kfra8p0\\LocalCache\\local-packages\\Python311\\site-packages\\keras\\src\\engine\\functional.py\", line 672, in _run_internal_graph\n\n  File \"C:\\Users\\harik\\AppData\\Local\\Packages\\PythonSoftwareFoundation.Python.3.11_qbz5n2kfra8p0\\LocalCache\\local-packages\\Python311\\site-packages\\keras\\src\\utils\\traceback_utils.py\", line 65, in error_handler\n\n  File \"C:\\Users\\harik\\AppData\\Local\\Packages\\PythonSoftwareFoundation.Python.3.11_qbz5n2kfra8p0\\LocalCache\\local-packages\\Python311\\site-packages\\keras\\src\\engine\\base_layer.py\", line 1149, in __call__\n\n  File \"C:\\Users\\harik\\AppData\\Local\\Packages\\PythonSoftwareFoundation.Python.3.11_qbz5n2kfra8p0\\LocalCache\\local-packages\\Python311\\site-packages\\keras\\src\\utils\\traceback_utils.py\", line 96, in error_handler\n\n  File \"C:\\Users\\harik\\AppData\\Local\\Packages\\PythonSoftwareFoundation.Python.3.11_qbz5n2kfra8p0\\LocalCache\\local-packages\\Python311\\site-packages\\keras\\src\\layers\\core\\embedding.py\", line 272, in call\n\nindices[9,1] = 17 is not in [0, 17)\n\t [[{{node sequential_4/embedding_1/embedding_lookup}}]] [Op:__inference_predict_function_406]",
      "\nDuring handling of the above exception, another exception occurred:\n",
      "\u001b[1;31mNameError\u001b[0m                                 Traceback (most recent call last)",
      "Cell \u001b[1;32mIn[31], line 7\u001b[0m\n\u001b[0;32m      5\u001b[0m \u001b[38;5;28mprint\u001b[39m(\u001b[38;5;124mf\u001b[39m\u001b[38;5;124m\"\u001b[39m\u001b[38;5;124mAn error occurred: \u001b[39m\u001b[38;5;132;01m{\u001b[39;00me\u001b[38;5;132;01m}\u001b[39;00m\u001b[38;5;124m\"\u001b[39m)\n\u001b[0;32m      6\u001b[0m \u001b[38;5;66;03m# Add additional information for debugging\u001b[39;00m\n\u001b[1;32m----> 7\u001b[0m \u001b[38;5;28mprint\u001b[39m(\u001b[38;5;124mf\u001b[39m\u001b[38;5;124m\"\u001b[39m\u001b[38;5;124mInput data shape: \u001b[39m\u001b[38;5;132;01m{\u001b[39;00m\u001b[43msequences\u001b[49m\u001b[38;5;241m.\u001b[39mshape\u001b[38;5;132;01m}\u001b[39;00m\u001b[38;5;124m\"\u001b[39m)\n\u001b[0;32m      8\u001b[0m \u001b[38;5;66;03m# Add more information as needed\u001b[39;00m\n\u001b[0;32m      9\u001b[0m \u001b[38;5;28;01mraise\u001b[39;00m e\n",
      "\u001b[1;31mNameError\u001b[0m: name 'sequences' is not defined"
     ]
    }
   ],
   "source": [
    "try:\n",
    "    pred = model.predict(seqeunces)\n",
    "    print(pred)\n",
    "except Exception as e:\n",
    "    print(f\"An error occurred: {e}\")\n",
    "    # Add additional information for debugging\n",
    "    print(f\"Input data shape: {sequences.shape}\")\n",
    "    # Add more information as needed\n",
    "    raise e\n"
   ]
  },
  {
   "cell_type": "code",
   "execution_count": 16,
   "id": "344bd9b2-b575-4d8c-b195-d4418716b13d",
   "metadata": {},
   "outputs": [],
   "source": [
    "from keras.datasets import imdb\n",
    "from keras.preprocessing.text import Tokenizer\n",
    "from keras.utils import pad_sequences\n",
    "from keras import Sequential\n",
    "from keras.layers import Dense,SimpleRNN,Embedding,Flatten"
   ]
  },
  {
   "cell_type": "code",
   "execution_count": null,
   "id": "5cb47d97-8a11-4d2d-8073-9044fea01b6a",
   "metadata": {},
   "outputs": [],
   "source": []
  }
 ],
 "metadata": {
  "kernelspec": {
   "display_name": "Python 3 (ipykernel)",
   "language": "python",
   "name": "python3"
  },
  "language_info": {
   "codemirror_mode": {
    "name": "ipython",
    "version": 3
   },
   "file_extension": ".py",
   "mimetype": "text/x-python",
   "name": "python",
   "nbconvert_exporter": "python",
   "pygments_lexer": "ipython3",
   "version": "3.11.7"
  },
  "widgets": {
   "application/vnd.jupyter.widget-state+json": {
    "state": {},
    "version_major": 2,
    "version_minor": 0
   }
  }
 },
 "nbformat": 4,
 "nbformat_minor": 5
}
